[2025-04-18T17:49:31.591+0000] {local_task_job_runner.py:123} INFO - ::group::Pre task execution logs
[2025-04-18T17:49:31.611+0000] {taskinstance.py:2613} INFO - Dependencies all met for dep_context=non-requeueable deps ti=<TaskInstance: weather_api_to_snowflake.dbt_tasks.dbt_debug manual__2025-04-18T17:49:19.474914+00:00 [queued]>
[2025-04-18T17:49:31.623+0000] {taskinstance.py:2613} INFO - Dependencies all met for dep_context=requeueable deps ti=<TaskInstance: weather_api_to_snowflake.dbt_tasks.dbt_debug manual__2025-04-18T17:49:19.474914+00:00 [queued]>
[2025-04-18T17:49:31.625+0000] {taskinstance.py:2866} INFO - Starting attempt 1 of 2
[2025-04-18T17:49:31.645+0000] {taskinstance.py:2889} INFO - Executing <Task(BashOperator): dbt_tasks.dbt_debug> on 2025-04-18 17:49:19.474914+00:00
[2025-04-18T17:49:31.653+0000] {standard_task_runner.py:72} INFO - Started process 1664 to run task
[2025-04-18T17:49:31.659+0000] {standard_task_runner.py:104} INFO - Running: ['***', 'tasks', 'run', 'weather_api_to_snowflake', 'dbt_tasks.dbt_debug', 'manual__2025-04-18T17:49:19.474914+00:00', '--job-id', '253', '--raw', '--subdir', 'DAGS_FOLDER/dbt_snowflake_pipeline.py', '--cfg-path', '/tmp/tmpzb_q90av']
[2025-04-18T17:49:31.665+0000] {standard_task_runner.py:105} INFO - Job 253: Subtask dbt_tasks.dbt_debug
[2025-04-18T17:49:31.723+0000] {task_command.py:467} INFO - Running <TaskInstance: weather_api_to_snowflake.dbt_tasks.dbt_debug manual__2025-04-18T17:49:19.474914+00:00 [running]> on host b322df8cb9fb
[2025-04-18T17:49:31.832+0000] {taskinstance.py:3132} INFO - Exporting env vars: AIRFLOW_CTX_DAG_OWNER='***' AIRFLOW_CTX_DAG_ID='weather_api_to_snowflake' AIRFLOW_CTX_TASK_ID='dbt_tasks.dbt_debug' AIRFLOW_CTX_EXECUTION_DATE='2025-04-18T17:49:19.474914+00:00' AIRFLOW_CTX_TRY_NUMBER='1' AIRFLOW_CTX_DAG_RUN_ID='manual__2025-04-18T17:49:19.474914+00:00'
[2025-04-18T17:49:31.835+0000] {taskinstance.py:731} INFO - ::endgroup::
[2025-04-18T17:49:31.856+0000] {subprocess.py:78} INFO - Tmp dir root location: /tmp
[2025-04-18T17:49:31.859+0000] {subprocess.py:88} INFO - Running command: ['/usr/bin/bash', '-c', '/home/***/.local/bin/dbt debug --project-dir /opt/dbt --profiles-dir /opt/dbt || true']
[2025-04-18T17:49:31.879+0000] {subprocess.py:99} INFO - Output:
[2025-04-18T17:49:36.357+0000] {subprocess.py:106} INFO - [0m17:49:36  Running with dbt=1.9.4
[2025-04-18T17:49:36.410+0000] {subprocess.py:106} INFO - [0m17:49:36  dbt version: 1.9.4
[2025-04-18T17:49:36.414+0000] {subprocess.py:106} INFO - [0m17:49:36  python version: 3.11.11
[2025-04-18T17:49:36.417+0000] {subprocess.py:106} INFO - [0m17:49:36  python path: /home/***/.local/bin/python
[2025-04-18T17:49:36.421+0000] {subprocess.py:106} INFO - [0m17:49:36  os info: Linux-5.10.76-linuxkit-x86_64-with-glibc2.36
[2025-04-18T17:49:37.703+0000] {subprocess.py:106} INFO - [0m17:49:37  Using profiles dir at /opt/dbt
[2025-04-18T17:49:37.706+0000] {subprocess.py:106} INFO - [0m17:49:37  Using profiles.yml file at /opt/dbt/profiles.yml
[2025-04-18T17:49:37.708+0000] {subprocess.py:106} INFO - [0m17:49:37  Using dbt_project.yml file at /opt/dbt/dbt_project.yml
[2025-04-18T17:49:37.713+0000] {subprocess.py:106} INFO - [0m17:49:37  adapter type: snowflake
[2025-04-18T17:49:37.715+0000] {subprocess.py:106} INFO - [0m17:49:37  adapter version: 1.9.2
[2025-04-18T17:49:37.860+0000] {subprocess.py:106} INFO - [0m17:49:37  Configuration:
[2025-04-18T17:49:37.863+0000] {subprocess.py:106} INFO - [0m17:49:37    profiles.yml file [[32mOK found and valid[0m]
[2025-04-18T17:49:37.865+0000] {subprocess.py:106} INFO - [0m17:49:37    dbt_project.yml file [[32mOK found and valid[0m]
[2025-04-18T17:49:37.868+0000] {subprocess.py:106} INFO - [0m17:49:37  Required dependencies:
[2025-04-18T17:49:37.875+0000] {subprocess.py:106} INFO - [0m17:49:37   - git [[31mERROR[0m]
[2025-04-18T17:49:37.878+0000] {subprocess.py:106} INFO - 
[2025-04-18T17:49:37.881+0000] {subprocess.py:106} INFO - [0m17:49:37  Connection:
[2025-04-18T17:49:37.883+0000] {subprocess.py:106} INFO - [0m17:49:37    account: dbjbmjn-gb63301
[2025-04-18T17:49:37.887+0000] {subprocess.py:106} INFO - [0m17:49:37    user: AIDASOW73
[2025-04-18T17:49:37.889+0000] {subprocess.py:106} INFO - [0m17:49:37    database: DBT_DOCKER_DEMO
[2025-04-18T17:49:37.892+0000] {subprocess.py:106} INFO - [0m17:49:37    warehouse: COMPUTE_WH
[2025-04-18T17:49:37.895+0000] {subprocess.py:106} INFO - [0m17:49:37    role: ACCOUNTADMIN
[2025-04-18T17:49:37.898+0000] {subprocess.py:106} INFO - [0m17:49:37    schema: BASE
[2025-04-18T17:49:37.901+0000] {subprocess.py:106} INFO - [0m17:49:37    authenticator: None
[2025-04-18T17:49:37.904+0000] {subprocess.py:106} INFO - [0m17:49:37    oauth_client_id: None
[2025-04-18T17:49:37.907+0000] {subprocess.py:106} INFO - [0m17:49:37    query_tag: None
[2025-04-18T17:49:37.910+0000] {subprocess.py:106} INFO - [0m17:49:37    client_session_keep_alive: False
[2025-04-18T17:49:37.913+0000] {subprocess.py:106} INFO - [0m17:49:37    host: None
[2025-04-18T17:49:37.917+0000] {subprocess.py:106} INFO - [0m17:49:37    port: None
[2025-04-18T17:49:37.920+0000] {subprocess.py:106} INFO - [0m17:49:37    proxy_host: None
[2025-04-18T17:49:37.924+0000] {subprocess.py:106} INFO - [0m17:49:37    proxy_port: None
[2025-04-18T17:49:37.928+0000] {subprocess.py:106} INFO - [0m17:49:37    protocol: None
[2025-04-18T17:49:37.931+0000] {subprocess.py:106} INFO - [0m17:49:37    connect_retries: 1
[2025-04-18T17:49:37.935+0000] {subprocess.py:106} INFO - [0m17:49:37    connect_timeout: None
[2025-04-18T17:49:37.938+0000] {subprocess.py:106} INFO - [0m17:49:37    retry_on_database_errors: False
[2025-04-18T17:49:37.941+0000] {subprocess.py:106} INFO - [0m17:49:37    retry_all: False
[2025-04-18T17:49:37.943+0000] {subprocess.py:106} INFO - [0m17:49:37    insecure_mode: False
[2025-04-18T17:49:37.946+0000] {subprocess.py:106} INFO - [0m17:49:37    reuse_connections: True
[2025-04-18T17:49:37.948+0000] {subprocess.py:106} INFO - [0m17:49:37  Registered adapter: snowflake=1.9.2
[2025-04-18T17:49:38.922+0000] {subprocess.py:106} INFO - [0m17:49:38    Connection test: [[32mOK connection ok[0m]
[2025-04-18T17:49:38.925+0000] {subprocess.py:106} INFO - 
[2025-04-18T17:49:38.929+0000] {subprocess.py:106} INFO - [0m17:49:38  [31m1 check failed:[0m
[2025-04-18T17:49:38.932+0000] {subprocess.py:106} INFO - [0m17:49:38  Error from git --help: Could not find command, ensure it is in the user's PATH: "git"
[2025-04-18T17:49:38.934+0000] {subprocess.py:106} INFO - 
[2025-04-18T17:49:40.118+0000] {subprocess.py:110} INFO - Command exited with return code 0
[2025-04-18T17:49:40.160+0000] {taskinstance.py:340} INFO - ::group::Post task execution logs
[2025-04-18T17:49:40.162+0000] {taskinstance.py:352} INFO - Marking task as SUCCESS. dag_id=weather_api_to_snowflake, task_id=dbt_tasks.dbt_debug, run_id=manual__2025-04-18T17:49:19.474914+00:00, execution_date=20250418T174919, start_date=20250418T174931, end_date=20250418T174940
[2025-04-18T17:49:40.225+0000] {local_task_job_runner.py:266} INFO - Task exited with return code 0
[2025-04-18T17:49:40.263+0000] {taskinstance.py:3895} INFO - 1 downstream tasks scheduled from follow-on schedule check
[2025-04-18T17:49:40.267+0000] {local_task_job_runner.py:245} INFO - ::endgroup::
