[2025-04-18T18:31:03.213+0000] {local_task_job_runner.py:123} INFO - ::group::Pre task execution logs
[2025-04-18T18:31:03.244+0000] {taskinstance.py:2613} INFO - Dependencies all met for dep_context=non-requeueable deps ti=<TaskInstance: weather_api_to_snowflake.dbt_tasks.dbt_debug manual__2025-04-18T18:27:08.156311+00:00 [queued]>
[2025-04-18T18:31:03.270+0000] {taskinstance.py:2613} INFO - Dependencies all met for dep_context=requeueable deps ti=<TaskInstance: weather_api_to_snowflake.dbt_tasks.dbt_debug manual__2025-04-18T18:27:08.156311+00:00 [queued]>
[2025-04-18T18:31:03.273+0000] {taskinstance.py:2866} INFO - Starting attempt 1 of 2
[2025-04-18T18:31:03.305+0000] {taskinstance.py:2889} INFO - Executing <Task(BashOperator): dbt_tasks.dbt_debug> on 2025-04-18 18:27:08.156311+00:00
[2025-04-18T18:31:03.322+0000] {standard_task_runner.py:72} INFO - Started process 2448 to run task
[2025-04-18T18:31:03.333+0000] {standard_task_runner.py:104} INFO - Running: ['***', 'tasks', 'run', 'weather_api_to_snowflake', 'dbt_tasks.dbt_debug', 'manual__2025-04-18T18:27:08.156311+00:00', '--job-id', '275', '--raw', '--subdir', 'DAGS_FOLDER/dbt_snowflake_pipeline.py', '--cfg-path', '/tmp/tmppf3y4omc']
[2025-04-18T18:31:03.346+0000] {standard_task_runner.py:105} INFO - Job 275: Subtask dbt_tasks.dbt_debug
[2025-04-18T18:31:03.732+0000] {task_command.py:467} INFO - Running <TaskInstance: weather_api_to_snowflake.dbt_tasks.dbt_debug manual__2025-04-18T18:27:08.156311+00:00 [running]> on host b322df8cb9fb
[2025-04-18T18:31:03.934+0000] {taskinstance.py:3132} INFO - Exporting env vars: AIRFLOW_CTX_DAG_OWNER='***' AIRFLOW_CTX_DAG_ID='weather_api_to_snowflake' AIRFLOW_CTX_TASK_ID='dbt_tasks.dbt_debug' AIRFLOW_CTX_EXECUTION_DATE='2025-04-18T18:27:08.156311+00:00' AIRFLOW_CTX_TRY_NUMBER='1' AIRFLOW_CTX_DAG_RUN_ID='manual__2025-04-18T18:27:08.156311+00:00'
[2025-04-18T18:31:03.937+0000] {taskinstance.py:731} INFO - ::endgroup::
[2025-04-18T18:31:04.003+0000] {subprocess.py:78} INFO - Tmp dir root location: /tmp
[2025-04-18T18:31:04.008+0000] {subprocess.py:88} INFO - Running command: ['/usr/bin/bash', '-c', '/home/***/.local/bin/dbt debug --project-dir /opt/dbt --profiles-dir /opt/dbt || true']
[2025-04-18T18:31:04.039+0000] {subprocess.py:99} INFO - Output:
[2025-04-18T18:31:09.691+0000] {subprocess.py:106} INFO - [0m18:31:09  Running with dbt=1.9.4
[2025-04-18T18:31:09.713+0000] {subprocess.py:106} INFO - [0m18:31:09  dbt version: 1.9.4
[2025-04-18T18:31:09.716+0000] {subprocess.py:106} INFO - [0m18:31:09  python version: 3.11.11
[2025-04-18T18:31:09.723+0000] {subprocess.py:106} INFO - [0m18:31:09  python path: /home/***/.local/bin/python
[2025-04-18T18:31:09.726+0000] {subprocess.py:106} INFO - [0m18:31:09  os info: Linux-5.10.76-linuxkit-x86_64-with-glibc2.36
[2025-04-18T18:31:11.664+0000] {subprocess.py:106} INFO - [0m18:31:11  Using profiles dir at /opt/dbt
[2025-04-18T18:31:11.668+0000] {subprocess.py:106} INFO - [0m18:31:11  Using profiles.yml file at /opt/dbt/profiles.yml
[2025-04-18T18:31:11.670+0000] {subprocess.py:106} INFO - [0m18:31:11  Using dbt_project.yml file at /opt/dbt/dbt_project.yml
[2025-04-18T18:31:11.673+0000] {subprocess.py:106} INFO - [0m18:31:11  adapter type: snowflake
[2025-04-18T18:31:11.674+0000] {subprocess.py:106} INFO - [0m18:31:11  adapter version: 1.9.2
[2025-04-18T18:31:11.809+0000] {subprocess.py:106} INFO - [0m18:31:11  Configuration:
[2025-04-18T18:31:11.811+0000] {subprocess.py:106} INFO - [0m18:31:11    profiles.yml file [[32mOK found and valid[0m]
[2025-04-18T18:31:11.815+0000] {subprocess.py:106} INFO - [0m18:31:11    dbt_project.yml file [[32mOK found and valid[0m]
[2025-04-18T18:31:11.817+0000] {subprocess.py:106} INFO - [0m18:31:11  Required dependencies:
[2025-04-18T18:31:11.823+0000] {subprocess.py:106} INFO - [0m18:31:11   - git [[31mERROR[0m]
[2025-04-18T18:31:11.826+0000] {subprocess.py:106} INFO - 
[2025-04-18T18:31:11.830+0000] {subprocess.py:106} INFO - [0m18:31:11  Connection:
[2025-04-18T18:31:11.832+0000] {subprocess.py:106} INFO - [0m18:31:11    account: dbjbmjn-gb63301
[2025-04-18T18:31:11.836+0000] {subprocess.py:106} INFO - [0m18:31:11    user: AIDASOW73
[2025-04-18T18:31:11.839+0000] {subprocess.py:106} INFO - [0m18:31:11    database: DBT_DOCKER_DEMO
[2025-04-18T18:31:11.842+0000] {subprocess.py:106} INFO - [0m18:31:11    warehouse: COMPUTE_WH
[2025-04-18T18:31:11.847+0000] {subprocess.py:106} INFO - [0m18:31:11    role: ACCOUNTADMIN
[2025-04-18T18:31:11.851+0000] {subprocess.py:106} INFO - [0m18:31:11    schema: BASE
[2025-04-18T18:31:11.853+0000] {subprocess.py:106} INFO - [0m18:31:11    authenticator: None
[2025-04-18T18:31:11.855+0000] {subprocess.py:106} INFO - [0m18:31:11    oauth_client_id: None
[2025-04-18T18:31:11.857+0000] {subprocess.py:106} INFO - [0m18:31:11    query_tag: None
[2025-04-18T18:31:11.859+0000] {subprocess.py:106} INFO - [0m18:31:11    client_session_keep_alive: False
[2025-04-18T18:31:11.863+0000] {subprocess.py:106} INFO - [0m18:31:11    host: None
[2025-04-18T18:31:11.867+0000] {subprocess.py:106} INFO - [0m18:31:11    port: None
[2025-04-18T18:31:11.869+0000] {subprocess.py:106} INFO - [0m18:31:11    proxy_host: None
[2025-04-18T18:31:11.871+0000] {subprocess.py:106} INFO - [0m18:31:11    proxy_port: None
[2025-04-18T18:31:11.874+0000] {subprocess.py:106} INFO - [0m18:31:11    protocol: None
[2025-04-18T18:31:11.877+0000] {subprocess.py:106} INFO - [0m18:31:11    connect_retries: 1
[2025-04-18T18:31:11.883+0000] {subprocess.py:106} INFO - [0m18:31:11    connect_timeout: None
[2025-04-18T18:31:11.886+0000] {subprocess.py:106} INFO - [0m18:31:11    retry_on_database_errors: False
[2025-04-18T18:31:11.890+0000] {subprocess.py:106} INFO - [0m18:31:11    retry_all: False
[2025-04-18T18:31:11.892+0000] {subprocess.py:106} INFO - [0m18:31:11    insecure_mode: False
[2025-04-18T18:31:11.895+0000] {subprocess.py:106} INFO - [0m18:31:11    reuse_connections: True
[2025-04-18T18:31:11.899+0000] {subprocess.py:106} INFO - [0m18:31:11  Registered adapter: snowflake=1.9.2
[2025-04-18T18:31:13.160+0000] {subprocess.py:106} INFO - [0m18:31:13    Connection test: [[32mOK connection ok[0m]
[2025-04-18T18:31:13.163+0000] {subprocess.py:106} INFO - 
[2025-04-18T18:31:13.165+0000] {subprocess.py:106} INFO - [0m18:31:13  [31m1 check failed:[0m
[2025-04-18T18:31:13.167+0000] {subprocess.py:106} INFO - [0m18:31:13  Error from git --help: Could not find command, ensure it is in the user's PATH: "git"
[2025-04-18T18:31:13.169+0000] {subprocess.py:106} INFO - 
[2025-04-18T18:31:14.427+0000] {subprocess.py:110} INFO - Command exited with return code 0
[2025-04-18T18:31:14.466+0000] {taskinstance.py:340} INFO - ::group::Post task execution logs
[2025-04-18T18:31:14.468+0000] {taskinstance.py:352} INFO - Marking task as SUCCESS. dag_id=weather_api_to_snowflake, task_id=dbt_tasks.dbt_debug, run_id=manual__2025-04-18T18:27:08.156311+00:00, execution_date=20250418T182708, start_date=20250418T183103, end_date=20250418T183114
[2025-04-18T18:31:14.541+0000] {local_task_job_runner.py:266} INFO - Task exited with return code 0
[2025-04-18T18:31:14.582+0000] {taskinstance.py:3895} INFO - 1 downstream tasks scheduled from follow-on schedule check
[2025-04-18T18:31:14.586+0000] {local_task_job_runner.py:245} INFO - ::endgroup::
