[2025-04-18T18:01:26.319+0000] {local_task_job_runner.py:123} INFO - ::group::Pre task execution logs
[2025-04-18T18:01:26.350+0000] {taskinstance.py:2613} INFO - Dependencies all met for dep_context=non-requeueable deps ti=<TaskInstance: weather_api_to_snowflake.dbt_tasks.dbt_debug manual__2025-04-18T18:01:09.977766+00:00 [queued]>
[2025-04-18T18:01:26.371+0000] {taskinstance.py:2613} INFO - Dependencies all met for dep_context=requeueable deps ti=<TaskInstance: weather_api_to_snowflake.dbt_tasks.dbt_debug manual__2025-04-18T18:01:09.977766+00:00 [queued]>
[2025-04-18T18:01:26.373+0000] {taskinstance.py:2866} INFO - Starting attempt 1 of 2
[2025-04-18T18:01:26.393+0000] {taskinstance.py:2889} INFO - Executing <Task(BashOperator): dbt_tasks.dbt_debug> on 2025-04-18 18:01:09.977766+00:00
[2025-04-18T18:01:26.407+0000] {standard_task_runner.py:72} INFO - Started process 1904 to run task
[2025-04-18T18:01:26.417+0000] {standard_task_runner.py:104} INFO - Running: ['***', 'tasks', 'run', 'weather_api_to_snowflake', 'dbt_tasks.dbt_debug', 'manual__2025-04-18T18:01:09.977766+00:00', '--job-id', '261', '--raw', '--subdir', 'DAGS_FOLDER/dbt_snowflake_pipeline.py', '--cfg-path', '/tmp/tmpdcziwmn9']
[2025-04-18T18:01:26.426+0000] {standard_task_runner.py:105} INFO - Job 261: Subtask dbt_tasks.dbt_debug
[2025-04-18T18:01:26.501+0000] {task_command.py:467} INFO - Running <TaskInstance: weather_api_to_snowflake.dbt_tasks.dbt_debug manual__2025-04-18T18:01:09.977766+00:00 [running]> on host b322df8cb9fb
[2025-04-18T18:01:26.683+0000] {taskinstance.py:3132} INFO - Exporting env vars: AIRFLOW_CTX_DAG_OWNER='***' AIRFLOW_CTX_DAG_ID='weather_api_to_snowflake' AIRFLOW_CTX_TASK_ID='dbt_tasks.dbt_debug' AIRFLOW_CTX_EXECUTION_DATE='2025-04-18T18:01:09.977766+00:00' AIRFLOW_CTX_TRY_NUMBER='1' AIRFLOW_CTX_DAG_RUN_ID='manual__2025-04-18T18:01:09.977766+00:00'
[2025-04-18T18:01:26.688+0000] {taskinstance.py:731} INFO - ::endgroup::
[2025-04-18T18:01:26.714+0000] {subprocess.py:78} INFO - Tmp dir root location: /tmp
[2025-04-18T18:01:26.736+0000] {subprocess.py:88} INFO - Running command: ['/usr/bin/bash', '-c', '/home/***/.local/bin/dbt debug --project-dir /opt/dbt --profiles-dir /opt/dbt || true']
[2025-04-18T18:01:26.771+0000] {subprocess.py:99} INFO - Output:
[2025-04-18T18:01:31.616+0000] {subprocess.py:106} INFO - [0m18:01:31  Running with dbt=1.9.4
[2025-04-18T18:01:31.668+0000] {subprocess.py:106} INFO - [0m18:01:31  dbt version: 1.9.4
[2025-04-18T18:01:31.682+0000] {subprocess.py:106} INFO - [0m18:01:31  python version: 3.11.11
[2025-04-18T18:01:31.701+0000] {subprocess.py:106} INFO - [0m18:01:31  python path: /home/***/.local/bin/python
[2025-04-18T18:01:31.721+0000] {subprocess.py:106} INFO - [0m18:01:31  os info: Linux-5.10.76-linuxkit-x86_64-with-glibc2.36
[2025-04-18T18:01:34.340+0000] {subprocess.py:106} INFO - [0m18:01:34  Using profiles dir at /opt/dbt
[2025-04-18T18:01:34.355+0000] {subprocess.py:106} INFO - [0m18:01:34  Using profiles.yml file at /opt/dbt/profiles.yml
[2025-04-18T18:01:34.357+0000] {subprocess.py:106} INFO - [0m18:01:34  Using dbt_project.yml file at /opt/dbt/dbt_project.yml
[2025-04-18T18:01:34.362+0000] {subprocess.py:106} INFO - [0m18:01:34  adapter type: snowflake
[2025-04-18T18:01:34.383+0000] {subprocess.py:106} INFO - [0m18:01:34  adapter version: 1.9.2
[2025-04-18T18:01:34.514+0000] {subprocess.py:106} INFO - [0m18:01:34  Configuration:
[2025-04-18T18:01:34.527+0000] {subprocess.py:106} INFO - [0m18:01:34    profiles.yml file [[32mOK found and valid[0m]
[2025-04-18T18:01:34.543+0000] {subprocess.py:106} INFO - [0m18:01:34    dbt_project.yml file [[32mOK found and valid[0m]
[2025-04-18T18:01:34.565+0000] {subprocess.py:106} INFO - [0m18:01:34  Required dependencies:
[2025-04-18T18:01:34.608+0000] {subprocess.py:106} INFO - [0m18:01:34   - git [[31mERROR[0m]
[2025-04-18T18:01:34.623+0000] {subprocess.py:106} INFO - 
[2025-04-18T18:01:34.643+0000] {subprocess.py:106} INFO - [0m18:01:34  Connection:
[2025-04-18T18:01:34.679+0000] {subprocess.py:106} INFO - [0m18:01:34    account: dbjbmjn-gb63301
[2025-04-18T18:01:34.732+0000] {subprocess.py:106} INFO - [0m18:01:34    user: AIDASOW73
[2025-04-18T18:01:34.753+0000] {subprocess.py:106} INFO - [0m18:01:34    database: DBT_DOCKER_DEMO
[2025-04-18T18:01:34.789+0000] {subprocess.py:106} INFO - [0m18:01:34    warehouse: COMPUTE_WH
[2025-04-18T18:01:34.818+0000] {subprocess.py:106} INFO - [0m18:01:34    role: ACCOUNTADMIN
[2025-04-18T18:01:34.837+0000] {subprocess.py:106} INFO - [0m18:01:34    schema: BASE
[2025-04-18T18:01:34.857+0000] {subprocess.py:106} INFO - [0m18:01:34    authenticator: None
[2025-04-18T18:01:34.878+0000] {subprocess.py:106} INFO - [0m18:01:34    oauth_client_id: None
[2025-04-18T18:01:34.885+0000] {subprocess.py:106} INFO - [0m18:01:34    query_tag: None
[2025-04-18T18:01:34.889+0000] {subprocess.py:106} INFO - [0m18:01:34    client_session_keep_alive: False
[2025-04-18T18:01:34.893+0000] {subprocess.py:106} INFO - [0m18:01:34    host: None
[2025-04-18T18:01:34.897+0000] {subprocess.py:106} INFO - [0m18:01:34    port: None
[2025-04-18T18:01:34.900+0000] {subprocess.py:106} INFO - [0m18:01:34    proxy_host: None
[2025-04-18T18:01:34.902+0000] {subprocess.py:106} INFO - [0m18:01:34    proxy_port: None
[2025-04-18T18:01:34.905+0000] {subprocess.py:106} INFO - [0m18:01:34    protocol: None
[2025-04-18T18:01:34.924+0000] {subprocess.py:106} INFO - [0m18:01:34    connect_retries: 1
[2025-04-18T18:01:34.944+0000] {subprocess.py:106} INFO - [0m18:01:34    connect_timeout: None
[2025-04-18T18:01:34.947+0000] {subprocess.py:106} INFO - [0m18:01:34    retry_on_database_errors: False
[2025-04-18T18:01:34.950+0000] {subprocess.py:106} INFO - [0m18:01:34    retry_all: False
[2025-04-18T18:01:34.952+0000] {subprocess.py:106} INFO - [0m18:01:34    insecure_mode: False
[2025-04-18T18:01:34.954+0000] {subprocess.py:106} INFO - [0m18:01:34    reuse_connections: True
[2025-04-18T18:01:34.957+0000] {subprocess.py:106} INFO - [0m18:01:34  Registered adapter: snowflake=1.9.2
[2025-04-18T18:01:36.168+0000] {subprocess.py:106} INFO - [0m18:01:36    Connection test: [[32mOK connection ok[0m]
[2025-04-18T18:01:36.186+0000] {subprocess.py:106} INFO - 
[2025-04-18T18:01:36.221+0000] {subprocess.py:106} INFO - [0m18:01:36  [31m1 check failed:[0m
[2025-04-18T18:01:36.223+0000] {subprocess.py:106} INFO - [0m18:01:36  Error from git --help: Could not find command, ensure it is in the user's PATH: "git"
[2025-04-18T18:01:36.225+0000] {subprocess.py:106} INFO - 
[2025-04-18T18:01:37.766+0000] {subprocess.py:110} INFO - Command exited with return code 0
[2025-04-18T18:01:37.813+0000] {taskinstance.py:340} INFO - ::group::Post task execution logs
[2025-04-18T18:01:37.816+0000] {taskinstance.py:352} INFO - Marking task as SUCCESS. dag_id=weather_api_to_snowflake, task_id=dbt_tasks.dbt_debug, run_id=manual__2025-04-18T18:01:09.977766+00:00, execution_date=20250418T180109, start_date=20250418T180126, end_date=20250418T180137
[2025-04-18T18:01:37.865+0000] {local_task_job_runner.py:266} INFO - Task exited with return code 0
[2025-04-18T18:01:37.904+0000] {taskinstance.py:3895} INFO - 1 downstream tasks scheduled from follow-on schedule check
[2025-04-18T18:01:37.908+0000] {local_task_job_runner.py:245} INFO - ::endgroup::
