[2025-04-18T17:32:03.871+0000] {local_task_job_runner.py:123} INFO - ::group::Pre task execution logs
[2025-04-18T17:32:03.905+0000] {taskinstance.py:2613} INFO - Dependencies all met for dep_context=non-requeueable deps ti=<TaskInstance: weather_api_to_snowflake.dbt_tasks.dbt_debug manual__2025-04-18T17:31:47.689986+00:00 [queued]>
[2025-04-18T17:32:03.924+0000] {taskinstance.py:2613} INFO - Dependencies all met for dep_context=requeueable deps ti=<TaskInstance: weather_api_to_snowflake.dbt_tasks.dbt_debug manual__2025-04-18T17:31:47.689986+00:00 [queued]>
[2025-04-18T17:32:03.926+0000] {taskinstance.py:2866} INFO - Starting attempt 1 of 2
[2025-04-18T17:32:03.952+0000] {taskinstance.py:2889} INFO - Executing <Task(BashOperator): dbt_tasks.dbt_debug> on 2025-04-18 17:31:47.689986+00:00
[2025-04-18T17:32:03.966+0000] {standard_task_runner.py:72} INFO - Started process 1366 to run task
[2025-04-18T17:32:03.975+0000] {standard_task_runner.py:104} INFO - Running: ['***', 'tasks', 'run', 'weather_api_to_snowflake', 'dbt_tasks.dbt_debug', 'manual__2025-04-18T17:31:47.689986+00:00', '--job-id', '246', '--raw', '--subdir', 'DAGS_FOLDER/dbt_snowflake_pipeline.py', '--cfg-path', '/tmp/tmpt2pg_usv']
[2025-04-18T17:32:03.986+0000] {standard_task_runner.py:105} INFO - Job 246: Subtask dbt_tasks.dbt_debug
[2025-04-18T17:32:04.101+0000] {task_command.py:467} INFO - Running <TaskInstance: weather_api_to_snowflake.dbt_tasks.dbt_debug manual__2025-04-18T17:31:47.689986+00:00 [running]> on host b322df8cb9fb
[2025-04-18T17:32:04.255+0000] {taskinstance.py:3132} INFO - Exporting env vars: AIRFLOW_CTX_DAG_OWNER='***' AIRFLOW_CTX_DAG_ID='weather_api_to_snowflake' AIRFLOW_CTX_TASK_ID='dbt_tasks.dbt_debug' AIRFLOW_CTX_EXECUTION_DATE='2025-04-18T17:31:47.689986+00:00' AIRFLOW_CTX_TRY_NUMBER='1' AIRFLOW_CTX_DAG_RUN_ID='manual__2025-04-18T17:31:47.689986+00:00'
[2025-04-18T17:32:04.260+0000] {taskinstance.py:731} INFO - ::endgroup::
[2025-04-18T17:32:04.292+0000] {subprocess.py:78} INFO - Tmp dir root location: /tmp
[2025-04-18T17:32:04.306+0000] {subprocess.py:88} INFO - Running command: ['/usr/bin/bash', '-c', '/home/***/.local/bin/dbt debug --project-dir /opt/dbt --profiles-dir /opt/dbt']
[2025-04-18T17:32:04.335+0000] {subprocess.py:99} INFO - Output:
[2025-04-18T17:32:09.041+0000] {subprocess.py:106} INFO - [0m17:32:09  Running with dbt=1.9.4
[2025-04-18T17:32:09.082+0000] {subprocess.py:106} INFO - [0m17:32:09  dbt version: 1.9.4
[2025-04-18T17:32:09.087+0000] {subprocess.py:106} INFO - [0m17:32:09  python version: 3.11.11
[2025-04-18T17:32:09.093+0000] {subprocess.py:106} INFO - [0m17:32:09  python path: /home/***/.local/bin/python
[2025-04-18T17:32:09.099+0000] {subprocess.py:106} INFO - [0m17:32:09  os info: Linux-5.10.76-linuxkit-x86_64-with-glibc2.36
[2025-04-18T17:32:10.898+0000] {subprocess.py:106} INFO - [0m17:32:10  Using profiles dir at /opt/dbt
[2025-04-18T17:32:10.901+0000] {subprocess.py:106} INFO - [0m17:32:10  Using profiles.yml file at /opt/dbt/profiles.yml
[2025-04-18T17:32:10.905+0000] {subprocess.py:106} INFO - [0m17:32:10  Using dbt_project.yml file at /opt/dbt/dbt_project.yml
[2025-04-18T17:32:10.907+0000] {subprocess.py:106} INFO - [0m17:32:10  adapter type: snowflake
[2025-04-18T17:32:10.913+0000] {subprocess.py:106} INFO - [0m17:32:10  adapter version: 1.9.2
[2025-04-18T17:32:11.055+0000] {subprocess.py:106} INFO - [0m17:32:11  Configuration:
[2025-04-18T17:32:11.058+0000] {subprocess.py:106} INFO - [0m17:32:11    profiles.yml file [[32mOK found and valid[0m]
[2025-04-18T17:32:11.061+0000] {subprocess.py:106} INFO - [0m17:32:11    dbt_project.yml file [[32mOK found and valid[0m]
[2025-04-18T17:32:11.064+0000] {subprocess.py:106} INFO - [0m17:32:11  Required dependencies:
[2025-04-18T17:32:11.071+0000] {subprocess.py:106} INFO - [0m17:32:11   - git [[31mERROR[0m]
[2025-04-18T17:32:11.074+0000] {subprocess.py:106} INFO - 
[2025-04-18T17:32:11.078+0000] {subprocess.py:106} INFO - [0m17:32:11  Connection:
[2025-04-18T17:32:11.081+0000] {subprocess.py:106} INFO - [0m17:32:11    account: dbjbmjn-gb63301
[2025-04-18T17:32:11.085+0000] {subprocess.py:106} INFO - [0m17:32:11    user: AIDASOW73
[2025-04-18T17:32:11.088+0000] {subprocess.py:106} INFO - [0m17:32:11    database: DBT_DOCKER_DEMO
[2025-04-18T17:32:11.091+0000] {subprocess.py:106} INFO - [0m17:32:11    warehouse: COMPUTE_WH
[2025-04-18T17:32:11.093+0000] {subprocess.py:106} INFO - [0m17:32:11    role: ACCOUNTADMIN
[2025-04-18T17:32:11.096+0000] {subprocess.py:106} INFO - [0m17:32:11    schema: BASE
[2025-04-18T17:32:11.098+0000] {subprocess.py:106} INFO - [0m17:32:11    authenticator: None
[2025-04-18T17:32:11.101+0000] {subprocess.py:106} INFO - [0m17:32:11    oauth_client_id: None
[2025-04-18T17:32:11.104+0000] {subprocess.py:106} INFO - [0m17:32:11    query_tag: None
[2025-04-18T17:32:11.108+0000] {subprocess.py:106} INFO - [0m17:32:11    client_session_keep_alive: False
[2025-04-18T17:32:11.111+0000] {subprocess.py:106} INFO - [0m17:32:11    host: None
[2025-04-18T17:32:11.113+0000] {subprocess.py:106} INFO - [0m17:32:11    port: None
[2025-04-18T17:32:11.115+0000] {subprocess.py:106} INFO - [0m17:32:11    proxy_host: None
[2025-04-18T17:32:11.117+0000] {subprocess.py:106} INFO - [0m17:32:11    proxy_port: None
[2025-04-18T17:32:11.119+0000] {subprocess.py:106} INFO - [0m17:32:11    protocol: None
[2025-04-18T17:32:11.121+0000] {subprocess.py:106} INFO - [0m17:32:11    connect_retries: 1
[2025-04-18T17:32:11.122+0000] {subprocess.py:106} INFO - [0m17:32:11    connect_timeout: None
[2025-04-18T17:32:11.125+0000] {subprocess.py:106} INFO - [0m17:32:11    retry_on_database_errors: False
[2025-04-18T17:32:11.127+0000] {subprocess.py:106} INFO - [0m17:32:11    retry_all: False
[2025-04-18T17:32:11.129+0000] {subprocess.py:106} INFO - [0m17:32:11    insecure_mode: False
[2025-04-18T17:32:11.131+0000] {subprocess.py:106} INFO - [0m17:32:11    reuse_connections: True
[2025-04-18T17:32:11.138+0000] {subprocess.py:106} INFO - [0m17:32:11  Registered adapter: snowflake=1.9.2
[2025-04-18T17:32:12.223+0000] {subprocess.py:106} INFO - [0m17:32:12    Connection test: [[32mOK connection ok[0m]
[2025-04-18T17:32:12.226+0000] {subprocess.py:106} INFO - 
[2025-04-18T17:32:12.228+0000] {subprocess.py:106} INFO - [0m17:32:12  [31m1 check failed:[0m
[2025-04-18T17:32:12.231+0000] {subprocess.py:106} INFO - [0m17:32:12  Error from git --help: Could not find command, ensure it is in the user's PATH: "git"
[2025-04-18T17:32:12.233+0000] {subprocess.py:106} INFO - 
[2025-04-18T17:32:13.890+0000] {subprocess.py:110} INFO - Command exited with return code 1
[2025-04-18T17:32:13.925+0000] {taskinstance.py:3311} ERROR - Task failed with exception
Traceback (most recent call last):
  File "/home/airflow/.local/lib/python3.11/site-packages/airflow/models/taskinstance.py", line 767, in _execute_task
    result = _execute_callable(context=context, **execute_callable_kwargs)
             ^^^^^^^^^^^^^^^^^^^^^^^^^^^^^^^^^^^^^^^^^^^^^^^^^^^^^^^^^^^^^
  File "/home/airflow/.local/lib/python3.11/site-packages/airflow/models/taskinstance.py", line 733, in _execute_callable
    return ExecutionCallableRunner(
           ^^^^^^^^^^^^^^^^^^^^^^^^
  File "/home/airflow/.local/lib/python3.11/site-packages/airflow/utils/operator_helpers.py", line 252, in run
    return self.func(*args, **kwargs)
           ^^^^^^^^^^^^^^^^^^^^^^^^^^
  File "/home/airflow/.local/lib/python3.11/site-packages/airflow/models/baseoperator.py", line 422, in wrapper
    return func(self, *args, **kwargs)
           ^^^^^^^^^^^^^^^^^^^^^^^^^^^
  File "/home/airflow/.local/lib/python3.11/site-packages/airflow/operators/bash.py", line 276, in execute
    raise AirflowException(
airflow.exceptions.AirflowException: Bash command failed. The command returned a non-zero exit code 1.
[2025-04-18T17:32:13.950+0000] {taskinstance.py:1225} INFO - Marking task as UP_FOR_RETRY. dag_id=weather_api_to_snowflake, task_id=dbt_tasks.dbt_debug, run_id=manual__2025-04-18T17:31:47.689986+00:00, execution_date=20250418T173147, start_date=20250418T173203, end_date=20250418T173213
[2025-04-18T17:32:13.991+0000] {taskinstance.py:340} INFO - ::group::Post task execution logs
[2025-04-18T17:32:13.996+0000] {standard_task_runner.py:124} ERROR - Failed to execute job 246 for task dbt_tasks.dbt_debug (Bash command failed. The command returned a non-zero exit code 1.; 1366)
Traceback (most recent call last):
  File "/home/airflow/.local/lib/python3.11/site-packages/airflow/task/task_runner/standard_task_runner.py", line 117, in _start_by_fork
    ret = args.func(args, dag=self.dag)
          ^^^^^^^^^^^^^^^^^^^^^^^^^^^^^
  File "/home/airflow/.local/lib/python3.11/site-packages/airflow/cli/cli_config.py", line 49, in command
    return func(*args, **kwargs)
           ^^^^^^^^^^^^^^^^^^^^^
  File "/home/airflow/.local/lib/python3.11/site-packages/airflow/utils/cli.py", line 116, in wrapper
    return f(*args, **kwargs)
           ^^^^^^^^^^^^^^^^^^
  File "/home/airflow/.local/lib/python3.11/site-packages/airflow/cli/commands/task_command.py", line 483, in task_run
    task_return_code = _run_task_by_selected_method(args, _dag, ti)
                       ^^^^^^^^^^^^^^^^^^^^^^^^^^^^^^^^^^^^^^^^^^^^
  File "/home/airflow/.local/lib/python3.11/site-packages/airflow/cli/commands/task_command.py", line 256, in _run_task_by_selected_method
    return _run_raw_task(args, ti)
           ^^^^^^^^^^^^^^^^^^^^^^^
  File "/home/airflow/.local/lib/python3.11/site-packages/airflow/cli/commands/task_command.py", line 341, in _run_raw_task
    return ti._run_raw_task(
           ^^^^^^^^^^^^^^^^^
  File "/home/airflow/.local/lib/python3.11/site-packages/airflow/utils/session.py", line 97, in wrapper
    return func(*args, session=session, **kwargs)
           ^^^^^^^^^^^^^^^^^^^^^^^^^^^^^^^^^^^^^^
  File "/home/airflow/.local/lib/python3.11/site-packages/airflow/models/taskinstance.py", line 3005, in _run_raw_task
    return _run_raw_task(
           ^^^^^^^^^^^^^^
  File "/home/airflow/.local/lib/python3.11/site-packages/airflow/models/taskinstance.py", line 273, in _run_raw_task
    TaskInstance._execute_task_with_callbacks(
  File "/home/airflow/.local/lib/python3.11/site-packages/airflow/models/taskinstance.py", line 3159, in _execute_task_with_callbacks
    result = self._execute_task(context, task_orig)
             ^^^^^^^^^^^^^^^^^^^^^^^^^^^^^^^^^^^^^^
  File "/home/airflow/.local/lib/python3.11/site-packages/airflow/models/taskinstance.py", line 3183, in _execute_task
    return _execute_task(self, context, task_orig)
           ^^^^^^^^^^^^^^^^^^^^^^^^^^^^^^^^^^^^^^^
  File "/home/airflow/.local/lib/python3.11/site-packages/airflow/models/taskinstance.py", line 767, in _execute_task
    result = _execute_callable(context=context, **execute_callable_kwargs)
             ^^^^^^^^^^^^^^^^^^^^^^^^^^^^^^^^^^^^^^^^^^^^^^^^^^^^^^^^^^^^^
  File "/home/airflow/.local/lib/python3.11/site-packages/airflow/models/taskinstance.py", line 733, in _execute_callable
    return ExecutionCallableRunner(
           ^^^^^^^^^^^^^^^^^^^^^^^^
  File "/home/airflow/.local/lib/python3.11/site-packages/airflow/utils/operator_helpers.py", line 252, in run
    return self.func(*args, **kwargs)
           ^^^^^^^^^^^^^^^^^^^^^^^^^^
  File "/home/airflow/.local/lib/python3.11/site-packages/airflow/models/baseoperator.py", line 422, in wrapper
    return func(self, *args, **kwargs)
           ^^^^^^^^^^^^^^^^^^^^^^^^^^^
  File "/home/airflow/.local/lib/python3.11/site-packages/airflow/operators/bash.py", line 276, in execute
    raise AirflowException(
airflow.exceptions.AirflowException: Bash command failed. The command returned a non-zero exit code 1.
[2025-04-18T17:32:14.070+0000] {local_task_job_runner.py:266} INFO - Task exited with return code 1
[2025-04-18T17:32:14.123+0000] {taskinstance.py:3895} INFO - 0 downstream tasks scheduled from follow-on schedule check
[2025-04-18T17:32:14.127+0000] {local_task_job_runner.py:245} INFO - ::endgroup::
