[2025-04-18T14:54:50.534+0000] {local_task_job_runner.py:123} INFO - ::group::Pre task execution logs
[2025-04-18T14:54:50.596+0000] {taskinstance.py:2613} INFO - Dependencies all met for dep_context=non-requeueable deps ti=<TaskInstance: weather_api_to_snowflake.weather_extraction_load.load_weather_raw_to_snowflake manual__2025-04-18T14:54:39.929164+00:00 [queued]>
[2025-04-18T14:54:50.625+0000] {taskinstance.py:2613} INFO - Dependencies all met for dep_context=requeueable deps ti=<TaskInstance: weather_api_to_snowflake.weather_extraction_load.load_weather_raw_to_snowflake manual__2025-04-18T14:54:39.929164+00:00 [queued]>
[2025-04-18T14:54:50.642+0000] {taskinstance.py:2866} INFO - Starting attempt 1 of 2
[2025-04-18T14:54:50.683+0000] {taskinstance.py:2889} INFO - Executing <Task(SnowflakeOperator): weather_extraction_load.load_weather_raw_to_snowflake> on 2025-04-18 14:54:39.929164+00:00
[2025-04-18T14:54:50.699+0000] {standard_task_runner.py:72} INFO - Started process 115 to run task
[2025-04-18T14:54:50.717+0000] {standard_task_runner.py:104} INFO - Running: ['***', 'tasks', 'run', 'weather_api_to_snowflake', 'weather_extraction_load.load_weather_raw_to_snowflake', 'manual__2025-04-18T14:54:39.929164+00:00', '--job-id', '214', '--raw', '--subdir', 'DAGS_FOLDER/dbt_snowflake_pipeline.py', '--cfg-path', '/tmp/tmp99l3whni']
[2025-04-18T14:54:50.738+0000] {standard_task_runner.py:105} INFO - Job 214: Subtask weather_extraction_load.load_weather_raw_to_snowflake
[2025-04-18T14:54:50.977+0000] {task_command.py:467} INFO - Running <TaskInstance: weather_api_to_snowflake.weather_extraction_load.load_weather_raw_to_snowflake manual__2025-04-18T14:54:39.929164+00:00 [running]> on host b322df8cb9fb
[2025-04-18T14:54:51.470+0000] {taskinstance.py:3132} INFO - Exporting env vars: AIRFLOW_CTX_DAG_OWNER='***' AIRFLOW_CTX_DAG_ID='weather_api_to_snowflake' AIRFLOW_CTX_TASK_ID='weather_extraction_load.load_weather_raw_to_snowflake' AIRFLOW_CTX_EXECUTION_DATE='2025-04-18T14:54:39.929164+00:00' AIRFLOW_CTX_TRY_NUMBER='1' AIRFLOW_CTX_DAG_RUN_ID='manual__2025-04-18T14:54:39.929164+00:00'
[2025-04-18T14:54:51.484+0000] {taskinstance.py:731} INFO - ::endgroup::
[2025-04-18T14:54:51.533+0000] {sql.py:278} INFO - Executing: None
[2025-04-18T14:54:51.570+0000] {base.py:84} INFO - Retrieving connection 'snowflake_conn'
[2025-04-18T14:54:51.599+0000] {base.py:84} INFO - Retrieving connection 'snowflake_conn'
[2025-04-18T14:54:51.603+0000] {connection.py:423} INFO - Snowflake Connector for Python Version: 3.14.0, Python Version: 3.11.11, Platform: Linux-5.10.76-linuxkit-x86_64-with-glibc2.36
[2025-04-18T14:54:51.608+0000] {connection.py:1226} INFO - Connecting to GLOBAL Snowflake domain
[2025-04-18T14:54:51.613+0000] {connection.py:1315} INFO - This connection is in OCSP Fail Open Mode. TLS Certificates would be checked for validity and revocation status. Any other Certificate Revocation related exceptions or OCSP Responder failures would be disregarded in favor of connectivity.
[2025-04-18T14:54:52.915+0000] {sql.py:553} INFO - Running statement: None, parameters: None
[2025-04-18T14:54:53.082+0000] {connection.py:810} INFO - closed
[2025-04-18T14:54:53.114+0000] {connection.py:816} INFO - No async queries seem to be running, deleting session
[2025-04-18T14:54:53.156+0000] {taskinstance.py:3311} ERROR - Task failed with exception
Traceback (most recent call last):
  File "/home/airflow/.local/lib/python3.11/site-packages/airflow/models/taskinstance.py", line 767, in _execute_task
    result = _execute_callable(context=context, **execute_callable_kwargs)
             ^^^^^^^^^^^^^^^^^^^^^^^^^^^^^^^^^^^^^^^^^^^^^^^^^^^^^^^^^^^^^
  File "/home/airflow/.local/lib/python3.11/site-packages/airflow/models/taskinstance.py", line 733, in _execute_callable
    return ExecutionCallableRunner(
           ^^^^^^^^^^^^^^^^^^^^^^^^
  File "/home/airflow/.local/lib/python3.11/site-packages/airflow/utils/operator_helpers.py", line 252, in run
    return self.func(*args, **kwargs)
           ^^^^^^^^^^^^^^^^^^^^^^^^^^
  File "/home/airflow/.local/lib/python3.11/site-packages/airflow/models/baseoperator.py", line 422, in wrapper
    return func(self, *args, **kwargs)
           ^^^^^^^^^^^^^^^^^^^^^^^^^^^
  File "/home/airflow/.local/lib/python3.11/site-packages/airflow/providers/common/sql/operators/sql.py", line 284, in execute
    output = hook.run(
             ^^^^^^^^^
  File "/home/airflow/.local/lib/python3.11/site-packages/airflow/providers/snowflake/hooks/snowflake.py", line 435, in run
    self._run_command(cur, sql_statement, parameters)  # type: ignore[attr-defined]
    ^^^^^^^^^^^^^^^^^^^^^^^^^^^^^^^^^^^^^^^^^^^^^^^^^
  File "/home/airflow/.local/lib/python3.11/site-packages/airflow/providers/common/sql/hooks/sql.py", line 558, in _run_command
    cur.execute(sql_statement)
  File "/home/airflow/.local/lib/python3.11/site-packages/snowflake/connector/cursor.py", line 1104, in execute
    Error.errorhandler_wrapper(self.connection, self, error_class, errvalue)
  File "/home/airflow/.local/lib/python3.11/site-packages/snowflake/connector/errors.py", line 283, in errorhandler_wrapper
    handed_over = Error.hand_to_other_handler(
                  ^^^^^^^^^^^^^^^^^^^^^^^^^^^^
  File "/home/airflow/.local/lib/python3.11/site-packages/snowflake/connector/errors.py", line 338, in hand_to_other_handler
    cursor.errorhandler(connection, cursor, error_class, error_value)
  File "/home/airflow/.local/lib/python3.11/site-packages/snowflake/connector/errors.py", line 214, in default_errorhandler
    raise error_class(
snowflake.connector.errors.ProgrammingError: 001003 (42000): 01bbc5fe-0001-532c-0001-2aee00014246: SQL compilation error:
syntax error line 1 at position 0 unexpected 'None'.
[2025-04-18T14:54:53.183+0000] {taskinstance.py:1225} INFO - Marking task as UP_FOR_RETRY. dag_id=weather_api_to_snowflake, task_id=weather_extraction_load.load_weather_raw_to_snowflake, run_id=manual__2025-04-18T14:54:39.929164+00:00, execution_date=20250418T145439, start_date=20250418T145450, end_date=20250418T145453
[2025-04-18T14:54:53.229+0000] {taskinstance.py:340} INFO - ::group::Post task execution logs
[2025-04-18T14:54:53.236+0000] {standard_task_runner.py:124} ERROR - Failed to execute job 214 for task weather_extraction_load.load_weather_raw_to_snowflake (001003 (42000): 01bbc5fe-0001-532c-0001-2aee00014246: SQL compilation error:
syntax error line 1 at position 0 unexpected 'None'.; 115)
Traceback (most recent call last):
  File "/home/airflow/.local/lib/python3.11/site-packages/airflow/task/task_runner/standard_task_runner.py", line 117, in _start_by_fork
    ret = args.func(args, dag=self.dag)
          ^^^^^^^^^^^^^^^^^^^^^^^^^^^^^
  File "/home/airflow/.local/lib/python3.11/site-packages/airflow/cli/cli_config.py", line 49, in command
    return func(*args, **kwargs)
           ^^^^^^^^^^^^^^^^^^^^^
  File "/home/airflow/.local/lib/python3.11/site-packages/airflow/utils/cli.py", line 116, in wrapper
    return f(*args, **kwargs)
           ^^^^^^^^^^^^^^^^^^
  File "/home/airflow/.local/lib/python3.11/site-packages/airflow/cli/commands/task_command.py", line 483, in task_run
    task_return_code = _run_task_by_selected_method(args, _dag, ti)
                       ^^^^^^^^^^^^^^^^^^^^^^^^^^^^^^^^^^^^^^^^^^^^
  File "/home/airflow/.local/lib/python3.11/site-packages/airflow/cli/commands/task_command.py", line 256, in _run_task_by_selected_method
    return _run_raw_task(args, ti)
           ^^^^^^^^^^^^^^^^^^^^^^^
  File "/home/airflow/.local/lib/python3.11/site-packages/airflow/cli/commands/task_command.py", line 341, in _run_raw_task
    return ti._run_raw_task(
           ^^^^^^^^^^^^^^^^^
  File "/home/airflow/.local/lib/python3.11/site-packages/airflow/utils/session.py", line 97, in wrapper
    return func(*args, session=session, **kwargs)
           ^^^^^^^^^^^^^^^^^^^^^^^^^^^^^^^^^^^^^^
  File "/home/airflow/.local/lib/python3.11/site-packages/airflow/models/taskinstance.py", line 3005, in _run_raw_task
    return _run_raw_task(
           ^^^^^^^^^^^^^^
  File "/home/airflow/.local/lib/python3.11/site-packages/airflow/models/taskinstance.py", line 273, in _run_raw_task
    TaskInstance._execute_task_with_callbacks(
  File "/home/airflow/.local/lib/python3.11/site-packages/airflow/models/taskinstance.py", line 3159, in _execute_task_with_callbacks
    result = self._execute_task(context, task_orig)
             ^^^^^^^^^^^^^^^^^^^^^^^^^^^^^^^^^^^^^^
  File "/home/airflow/.local/lib/python3.11/site-packages/airflow/models/taskinstance.py", line 3183, in _execute_task
    return _execute_task(self, context, task_orig)
           ^^^^^^^^^^^^^^^^^^^^^^^^^^^^^^^^^^^^^^^
  File "/home/airflow/.local/lib/python3.11/site-packages/airflow/models/taskinstance.py", line 767, in _execute_task
    result = _execute_callable(context=context, **execute_callable_kwargs)
             ^^^^^^^^^^^^^^^^^^^^^^^^^^^^^^^^^^^^^^^^^^^^^^^^^^^^^^^^^^^^^
  File "/home/airflow/.local/lib/python3.11/site-packages/airflow/models/taskinstance.py", line 733, in _execute_callable
    return ExecutionCallableRunner(
           ^^^^^^^^^^^^^^^^^^^^^^^^
  File "/home/airflow/.local/lib/python3.11/site-packages/airflow/utils/operator_helpers.py", line 252, in run
    return self.func(*args, **kwargs)
           ^^^^^^^^^^^^^^^^^^^^^^^^^^
  File "/home/airflow/.local/lib/python3.11/site-packages/airflow/models/baseoperator.py", line 422, in wrapper
    return func(self, *args, **kwargs)
           ^^^^^^^^^^^^^^^^^^^^^^^^^^^
  File "/home/airflow/.local/lib/python3.11/site-packages/airflow/providers/common/sql/operators/sql.py", line 284, in execute
    output = hook.run(
             ^^^^^^^^^
  File "/home/airflow/.local/lib/python3.11/site-packages/airflow/providers/snowflake/hooks/snowflake.py", line 435, in run
    self._run_command(cur, sql_statement, parameters)  # type: ignore[attr-defined]
    ^^^^^^^^^^^^^^^^^^^^^^^^^^^^^^^^^^^^^^^^^^^^^^^^^
  File "/home/airflow/.local/lib/python3.11/site-packages/airflow/providers/common/sql/hooks/sql.py", line 558, in _run_command
    cur.execute(sql_statement)
  File "/home/airflow/.local/lib/python3.11/site-packages/snowflake/connector/cursor.py", line 1104, in execute
    Error.errorhandler_wrapper(self.connection, self, error_class, errvalue)
  File "/home/airflow/.local/lib/python3.11/site-packages/snowflake/connector/errors.py", line 283, in errorhandler_wrapper
    handed_over = Error.hand_to_other_handler(
                  ^^^^^^^^^^^^^^^^^^^^^^^^^^^^
  File "/home/airflow/.local/lib/python3.11/site-packages/snowflake/connector/errors.py", line 338, in hand_to_other_handler
    cursor.errorhandler(connection, cursor, error_class, error_value)
  File "/home/airflow/.local/lib/python3.11/site-packages/snowflake/connector/errors.py", line 214, in default_errorhandler
    raise error_class(
snowflake.connector.errors.ProgrammingError: 001003 (42000): 01bbc5fe-0001-532c-0001-2aee00014246: SQL compilation error:
syntax error line 1 at position 0 unexpected 'None'.
[2025-04-18T14:54:53.295+0000] {local_task_job_runner.py:266} INFO - Task exited with return code 1
[2025-04-18T14:54:53.339+0000] {taskinstance.py:3895} INFO - 0 downstream tasks scheduled from follow-on schedule check
[2025-04-18T14:54:53.346+0000] {local_task_job_runner.py:245} INFO - ::endgroup::
