[2025-04-18T15:37:11.912+0000] {local_task_job_runner.py:123} INFO - ::group::Pre task execution logs
[2025-04-18T15:37:11.938+0000] {taskinstance.py:2613} INFO - Dependencies all met for dep_context=non-requeueable deps ti=<TaskInstance: weather_api_to_snowflake.dbt_tasks.dbt_debug manual__2025-04-18T15:36:59.425848+00:00 [queued]>
[2025-04-18T15:37:11.954+0000] {taskinstance.py:2613} INFO - Dependencies all met for dep_context=requeueable deps ti=<TaskInstance: weather_api_to_snowflake.dbt_tasks.dbt_debug manual__2025-04-18T15:36:59.425848+00:00 [queued]>
[2025-04-18T15:37:11.956+0000] {taskinstance.py:2866} INFO - Starting attempt 1 of 2
[2025-04-18T15:37:11.980+0000] {taskinstance.py:2889} INFO - Executing <Task(BashOperator): dbt_tasks.dbt_debug> on 2025-04-18 15:36:59.425848+00:00
[2025-04-18T15:37:11.997+0000] {standard_task_runner.py:72} INFO - Started process 689 to run task
[2025-04-18T15:37:12.004+0000] {standard_task_runner.py:104} INFO - Running: ['***', 'tasks', 'run', 'weather_api_to_snowflake', 'dbt_tasks.dbt_debug', 'manual__2025-04-18T15:36:59.425848+00:00', '--job-id', '226', '--raw', '--subdir', 'DAGS_FOLDER/dbt_snowflake_pipeline.py', '--cfg-path', '/tmp/tmpbf8wm3b_']
[2025-04-18T15:37:12.013+0000] {standard_task_runner.py:105} INFO - Job 226: Subtask dbt_tasks.dbt_debug
[2025-04-18T15:37:12.115+0000] {task_command.py:467} INFO - Running <TaskInstance: weather_api_to_snowflake.dbt_tasks.dbt_debug manual__2025-04-18T15:36:59.425848+00:00 [running]> on host b322df8cb9fb
[2025-04-18T15:37:12.271+0000] {taskinstance.py:3132} INFO - Exporting env vars: AIRFLOW_CTX_DAG_OWNER='***' AIRFLOW_CTX_DAG_ID='weather_api_to_snowflake' AIRFLOW_CTX_TASK_ID='dbt_tasks.dbt_debug' AIRFLOW_CTX_EXECUTION_DATE='2025-04-18T15:36:59.425848+00:00' AIRFLOW_CTX_TRY_NUMBER='1' AIRFLOW_CTX_DAG_RUN_ID='manual__2025-04-18T15:36:59.425848+00:00'
[2025-04-18T15:37:12.275+0000] {taskinstance.py:731} INFO - ::endgroup::
[2025-04-18T15:37:12.298+0000] {subprocess.py:78} INFO - Tmp dir root location: /tmp
[2025-04-18T15:37:12.301+0000] {subprocess.py:88} INFO - Running command: ['/usr/bin/bash', '-c', 'dbt debug --project-dir /opt/dbt --profiles-dir /opt/dbt']
[2025-04-18T15:37:12.325+0000] {subprocess.py:99} INFO - Output:
[2025-04-18T15:37:16.083+0000] {subprocess.py:106} INFO - [0m15:37:16  Running with dbt=1.9.4
[2025-04-18T15:37:16.109+0000] {subprocess.py:106} INFO - [0m15:37:16  dbt version: 1.9.4
[2025-04-18T15:37:16.112+0000] {subprocess.py:106} INFO - [0m15:37:16  python version: 3.11.11
[2025-04-18T15:37:16.116+0000] {subprocess.py:106} INFO - [0m15:37:16  python path: /home/***/.local/bin/python
[2025-04-18T15:37:16.118+0000] {subprocess.py:106} INFO - [0m15:37:16  os info: Linux-5.10.76-linuxkit-x86_64-with-glibc2.36
[2025-04-18T15:37:16.136+0000] {subprocess.py:106} INFO - [0m15:37:16  Encountered an error:
[2025-04-18T15:37:16.138+0000] {subprocess.py:106} INFO - Parsing Error
[2025-04-18T15:37:16.140+0000] {subprocess.py:106} INFO -   Env var required but not provided: 'SNOWFLAKE_ACCOUNT'
[2025-04-18T15:37:16.889+0000] {subprocess.py:110} INFO - Command exited with return code 2
[2025-04-18T15:37:16.908+0000] {taskinstance.py:3311} ERROR - Task failed with exception
Traceback (most recent call last):
  File "/home/airflow/.local/lib/python3.11/site-packages/airflow/models/taskinstance.py", line 767, in _execute_task
    result = _execute_callable(context=context, **execute_callable_kwargs)
             ^^^^^^^^^^^^^^^^^^^^^^^^^^^^^^^^^^^^^^^^^^^^^^^^^^^^^^^^^^^^^
  File "/home/airflow/.local/lib/python3.11/site-packages/airflow/models/taskinstance.py", line 733, in _execute_callable
    return ExecutionCallableRunner(
           ^^^^^^^^^^^^^^^^^^^^^^^^
  File "/home/airflow/.local/lib/python3.11/site-packages/airflow/utils/operator_helpers.py", line 252, in run
    return self.func(*args, **kwargs)
           ^^^^^^^^^^^^^^^^^^^^^^^^^^
  File "/home/airflow/.local/lib/python3.11/site-packages/airflow/models/baseoperator.py", line 422, in wrapper
    return func(self, *args, **kwargs)
           ^^^^^^^^^^^^^^^^^^^^^^^^^^^
  File "/home/airflow/.local/lib/python3.11/site-packages/airflow/operators/bash.py", line 276, in execute
    raise AirflowException(
airflow.exceptions.AirflowException: Bash command failed. The command returned a non-zero exit code 2.
[2025-04-18T15:37:16.928+0000] {taskinstance.py:1225} INFO - Marking task as UP_FOR_RETRY. dag_id=weather_api_to_snowflake, task_id=dbt_tasks.dbt_debug, run_id=manual__2025-04-18T15:36:59.425848+00:00, execution_date=20250418T153659, start_date=20250418T153711, end_date=20250418T153716
[2025-04-18T15:37:16.953+0000] {taskinstance.py:340} INFO - ::group::Post task execution logs
[2025-04-18T15:37:16.955+0000] {standard_task_runner.py:124} ERROR - Failed to execute job 226 for task dbt_tasks.dbt_debug (Bash command failed. The command returned a non-zero exit code 2.; 689)
Traceback (most recent call last):
  File "/home/airflow/.local/lib/python3.11/site-packages/airflow/task/task_runner/standard_task_runner.py", line 117, in _start_by_fork
    ret = args.func(args, dag=self.dag)
          ^^^^^^^^^^^^^^^^^^^^^^^^^^^^^
  File "/home/airflow/.local/lib/python3.11/site-packages/airflow/cli/cli_config.py", line 49, in command
    return func(*args, **kwargs)
           ^^^^^^^^^^^^^^^^^^^^^
  File "/home/airflow/.local/lib/python3.11/site-packages/airflow/utils/cli.py", line 116, in wrapper
    return f(*args, **kwargs)
           ^^^^^^^^^^^^^^^^^^
  File "/home/airflow/.local/lib/python3.11/site-packages/airflow/cli/commands/task_command.py", line 483, in task_run
    task_return_code = _run_task_by_selected_method(args, _dag, ti)
                       ^^^^^^^^^^^^^^^^^^^^^^^^^^^^^^^^^^^^^^^^^^^^
  File "/home/airflow/.local/lib/python3.11/site-packages/airflow/cli/commands/task_command.py", line 256, in _run_task_by_selected_method
    return _run_raw_task(args, ti)
           ^^^^^^^^^^^^^^^^^^^^^^^
  File "/home/airflow/.local/lib/python3.11/site-packages/airflow/cli/commands/task_command.py", line 341, in _run_raw_task
    return ti._run_raw_task(
           ^^^^^^^^^^^^^^^^^
  File "/home/airflow/.local/lib/python3.11/site-packages/airflow/utils/session.py", line 97, in wrapper
    return func(*args, session=session, **kwargs)
           ^^^^^^^^^^^^^^^^^^^^^^^^^^^^^^^^^^^^^^
  File "/home/airflow/.local/lib/python3.11/site-packages/airflow/models/taskinstance.py", line 3005, in _run_raw_task
    return _run_raw_task(
           ^^^^^^^^^^^^^^
  File "/home/airflow/.local/lib/python3.11/site-packages/airflow/models/taskinstance.py", line 273, in _run_raw_task
    TaskInstance._execute_task_with_callbacks(
  File "/home/airflow/.local/lib/python3.11/site-packages/airflow/models/taskinstance.py", line 3159, in _execute_task_with_callbacks
    result = self._execute_task(context, task_orig)
             ^^^^^^^^^^^^^^^^^^^^^^^^^^^^^^^^^^^^^^
  File "/home/airflow/.local/lib/python3.11/site-packages/airflow/models/taskinstance.py", line 3183, in _execute_task
    return _execute_task(self, context, task_orig)
           ^^^^^^^^^^^^^^^^^^^^^^^^^^^^^^^^^^^^^^^
  File "/home/airflow/.local/lib/python3.11/site-packages/airflow/models/taskinstance.py", line 767, in _execute_task
    result = _execute_callable(context=context, **execute_callable_kwargs)
             ^^^^^^^^^^^^^^^^^^^^^^^^^^^^^^^^^^^^^^^^^^^^^^^^^^^^^^^^^^^^^
  File "/home/airflow/.local/lib/python3.11/site-packages/airflow/models/taskinstance.py", line 733, in _execute_callable
    return ExecutionCallableRunner(
           ^^^^^^^^^^^^^^^^^^^^^^^^
  File "/home/airflow/.local/lib/python3.11/site-packages/airflow/utils/operator_helpers.py", line 252, in run
    return self.func(*args, **kwargs)
           ^^^^^^^^^^^^^^^^^^^^^^^^^^
  File "/home/airflow/.local/lib/python3.11/site-packages/airflow/models/baseoperator.py", line 422, in wrapper
    return func(self, *args, **kwargs)
           ^^^^^^^^^^^^^^^^^^^^^^^^^^^
  File "/home/airflow/.local/lib/python3.11/site-packages/airflow/operators/bash.py", line 276, in execute
    raise AirflowException(
airflow.exceptions.AirflowException: Bash command failed. The command returned a non-zero exit code 2.
[2025-04-18T15:37:17.007+0000] {local_task_job_runner.py:266} INFO - Task exited with return code 1
[2025-04-18T15:37:17.021+0000] {standard_task_runner.py:217} INFO - Process not found (most likely exited), stop collecting metrics
[2025-04-18T15:37:17.050+0000] {taskinstance.py:3895} INFO - 0 downstream tasks scheduled from follow-on schedule check
[2025-04-18T15:37:17.054+0000] {local_task_job_runner.py:245} INFO - ::endgroup::
