[2025-04-17T13:37:00.694+0000] {local_task_job_runner.py:123} INFO - ::group::Pre task execution logs
[2025-04-17T13:37:00.734+0000] {taskinstance.py:2613} INFO - Dependencies all met for dep_context=non-requeueable deps ti=<TaskInstance: weather_api_to_snowflake.load_weather manual__2025-04-17T13:36:51.642882+00:00 [queued]>
[2025-04-17T13:37:00.750+0000] {taskinstance.py:2613} INFO - Dependencies all met for dep_context=requeueable deps ti=<TaskInstance: weather_api_to_snowflake.load_weather manual__2025-04-17T13:36:51.642882+00:00 [queued]>
[2025-04-17T13:37:00.752+0000] {taskinstance.py:2866} INFO - Starting attempt 1 of 2
[2025-04-17T13:37:00.778+0000] {taskinstance.py:2889} INFO - Executing <Task(PythonOperator): load_weather> on 2025-04-17 13:36:51.642882+00:00
[2025-04-17T13:37:00.791+0000] {standard_task_runner.py:72} INFO - Started process 401 to run task
[2025-04-17T13:37:00.798+0000] {standard_task_runner.py:104} INFO - Running: ['***', 'tasks', 'run', 'weather_api_to_snowflake', 'load_weather', 'manual__2025-04-17T13:36:51.642882+00:00', '--job-id', '16', '--raw', '--subdir', 'DAGS_FOLDER/dbt_snowflake_pipeline.py', '--cfg-path', '/tmp/tmpny89mqh9']
[2025-04-17T13:37:00.806+0000] {standard_task_runner.py:105} INFO - Job 16: Subtask load_weather
[2025-04-17T13:37:00.935+0000] {task_command.py:467} INFO - Running <TaskInstance: weather_api_to_snowflake.load_weather manual__2025-04-17T13:36:51.642882+00:00 [running]> on host b322df8cb9fb
[2025-04-17T13:37:01.070+0000] {taskinstance.py:3132} INFO - Exporting env vars: AIRFLOW_CTX_DAG_OWNER='***' AIRFLOW_CTX_DAG_ID='weather_api_to_snowflake' AIRFLOW_CTX_TASK_ID='load_weather' AIRFLOW_CTX_EXECUTION_DATE='2025-04-17T13:36:51.642882+00:00' AIRFLOW_CTX_TRY_NUMBER='1' AIRFLOW_CTX_DAG_RUN_ID='manual__2025-04-17T13:36:51.642882+00:00'
[2025-04-17T13:37:01.077+0000] {taskinstance.py:731} INFO - ::endgroup::
[2025-04-17T13:37:01.134+0000] {connection.py:423} INFO - Snowflake Connector for Python Version: 3.14.0, Python Version: 3.11.11, Platform: Linux-5.10.76-linuxkit-x86_64-with-glibc2.36
[2025-04-17T13:37:01.141+0000] {taskinstance.py:3311} ERROR - Task failed with exception
Traceback (most recent call last):
  File "/home/airflow/.local/lib/python3.11/site-packages/airflow/models/taskinstance.py", line 767, in _execute_task
    result = _execute_callable(context=context, **execute_callable_kwargs)
             ^^^^^^^^^^^^^^^^^^^^^^^^^^^^^^^^^^^^^^^^^^^^^^^^^^^^^^^^^^^^^
  File "/home/airflow/.local/lib/python3.11/site-packages/airflow/models/taskinstance.py", line 733, in _execute_callable
    return ExecutionCallableRunner(
           ^^^^^^^^^^^^^^^^^^^^^^^^
  File "/home/airflow/.local/lib/python3.11/site-packages/airflow/utils/operator_helpers.py", line 252, in run
    return self.func(*args, **kwargs)
           ^^^^^^^^^^^^^^^^^^^^^^^^^^
  File "/home/airflow/.local/lib/python3.11/site-packages/airflow/models/baseoperator.py", line 422, in wrapper
    return func(self, *args, **kwargs)
           ^^^^^^^^^^^^^^^^^^^^^^^^^^^
  File "/home/airflow/.local/lib/python3.11/site-packages/airflow/operators/python.py", line 238, in execute
    return_value = self.execute_callable()
                   ^^^^^^^^^^^^^^^^^^^^^^^
  File "/home/airflow/.local/lib/python3.11/site-packages/airflow/operators/python.py", line 256, in execute_callable
    return runner.run(*self.op_args, **self.op_kwargs)
           ^^^^^^^^^^^^^^^^^^^^^^^^^^^^^^^^^^^^^^^^^^^
  File "/home/airflow/.local/lib/python3.11/site-packages/airflow/utils/operator_helpers.py", line 252, in run
    return self.func(*args, **kwargs)
           ^^^^^^^^^^^^^^^^^^^^^^^^^^
  File "/opt/airflow/dags/dbt_snowflake_pipeline.py", line 37, in load_into_snowflake
    conn = snowflake.connector.connect(
           ^^^^^^^^^^^^^^^^^^^^^^^^^^^^
  File "/home/airflow/.local/lib/python3.11/site-packages/snowflake/connector/__init__.py", line 55, in Connect
    return SnowflakeConnection(**kwargs)
           ^^^^^^^^^^^^^^^^^^^^^^^^^^^^^
  File "/home/airflow/.local/lib/python3.11/site-packages/snowflake/connector/connection.py", line 466, in __init__
    self.connect(**kwargs)
  File "/home/airflow/.local/lib/python3.11/site-packages/snowflake/connector/connection.py", line 754, in connect
    self.__config(**kwargs)
  File "/home/airflow/.local/lib/python3.11/site-packages/snowflake/connector/connection.py", line 1215, in __config
    self._host = construct_hostname(kwargs.get("region"), self._account)
                 ^^^^^^^^^^^^^^^^^^^^^^^^^^^^^^^^^^^^^^^^^^^^^^^^^^^^^^^
  File "/home/airflow/.local/lib/python3.11/site-packages/snowflake/connector/util_text.py", line 255, in construct_hostname
    if account.find(".") > 0 and _is_china_region(account.split(".")[1]):
       ^^^^^^^^^^^^
AttributeError: 'NoneType' object has no attribute 'find'
[2025-04-17T13:37:01.230+0000] {taskinstance.py:1225} INFO - Marking task as UP_FOR_RETRY. dag_id=weather_api_to_snowflake, task_id=load_weather, run_id=manual__2025-04-17T13:36:51.642882+00:00, execution_date=20250417T133651, start_date=20250417T133700, end_date=20250417T133701
[2025-04-17T13:37:01.284+0000] {taskinstance.py:340} INFO - ::group::Post task execution logs
[2025-04-17T13:37:01.290+0000] {standard_task_runner.py:124} ERROR - Failed to execute job 16 for task load_weather ('NoneType' object has no attribute 'find'; 401)
Traceback (most recent call last):
  File "/home/airflow/.local/lib/python3.11/site-packages/airflow/task/task_runner/standard_task_runner.py", line 117, in _start_by_fork
    ret = args.func(args, dag=self.dag)
          ^^^^^^^^^^^^^^^^^^^^^^^^^^^^^
  File "/home/airflow/.local/lib/python3.11/site-packages/airflow/cli/cli_config.py", line 49, in command
    return func(*args, **kwargs)
           ^^^^^^^^^^^^^^^^^^^^^
  File "/home/airflow/.local/lib/python3.11/site-packages/airflow/utils/cli.py", line 116, in wrapper
    return f(*args, **kwargs)
           ^^^^^^^^^^^^^^^^^^
  File "/home/airflow/.local/lib/python3.11/site-packages/airflow/cli/commands/task_command.py", line 483, in task_run
    task_return_code = _run_task_by_selected_method(args, _dag, ti)
                       ^^^^^^^^^^^^^^^^^^^^^^^^^^^^^^^^^^^^^^^^^^^^
  File "/home/airflow/.local/lib/python3.11/site-packages/airflow/cli/commands/task_command.py", line 256, in _run_task_by_selected_method
    return _run_raw_task(args, ti)
           ^^^^^^^^^^^^^^^^^^^^^^^
  File "/home/airflow/.local/lib/python3.11/site-packages/airflow/cli/commands/task_command.py", line 341, in _run_raw_task
    return ti._run_raw_task(
           ^^^^^^^^^^^^^^^^^
  File "/home/airflow/.local/lib/python3.11/site-packages/airflow/utils/session.py", line 97, in wrapper
    return func(*args, session=session, **kwargs)
           ^^^^^^^^^^^^^^^^^^^^^^^^^^^^^^^^^^^^^^
  File "/home/airflow/.local/lib/python3.11/site-packages/airflow/models/taskinstance.py", line 3005, in _run_raw_task
    return _run_raw_task(
           ^^^^^^^^^^^^^^
  File "/home/airflow/.local/lib/python3.11/site-packages/airflow/models/taskinstance.py", line 273, in _run_raw_task
    TaskInstance._execute_task_with_callbacks(
  File "/home/airflow/.local/lib/python3.11/site-packages/airflow/models/taskinstance.py", line 3159, in _execute_task_with_callbacks
    result = self._execute_task(context, task_orig)
             ^^^^^^^^^^^^^^^^^^^^^^^^^^^^^^^^^^^^^^
  File "/home/airflow/.local/lib/python3.11/site-packages/airflow/models/taskinstance.py", line 3183, in _execute_task
    return _execute_task(self, context, task_orig)
           ^^^^^^^^^^^^^^^^^^^^^^^^^^^^^^^^^^^^^^^
  File "/home/airflow/.local/lib/python3.11/site-packages/airflow/models/taskinstance.py", line 767, in _execute_task
    result = _execute_callable(context=context, **execute_callable_kwargs)
             ^^^^^^^^^^^^^^^^^^^^^^^^^^^^^^^^^^^^^^^^^^^^^^^^^^^^^^^^^^^^^
  File "/home/airflow/.local/lib/python3.11/site-packages/airflow/models/taskinstance.py", line 733, in _execute_callable
    return ExecutionCallableRunner(
           ^^^^^^^^^^^^^^^^^^^^^^^^
  File "/home/airflow/.local/lib/python3.11/site-packages/airflow/utils/operator_helpers.py", line 252, in run
    return self.func(*args, **kwargs)
           ^^^^^^^^^^^^^^^^^^^^^^^^^^
  File "/home/airflow/.local/lib/python3.11/site-packages/airflow/models/baseoperator.py", line 422, in wrapper
    return func(self, *args, **kwargs)
           ^^^^^^^^^^^^^^^^^^^^^^^^^^^
  File "/home/airflow/.local/lib/python3.11/site-packages/airflow/operators/python.py", line 238, in execute
    return_value = self.execute_callable()
                   ^^^^^^^^^^^^^^^^^^^^^^^
  File "/home/airflow/.local/lib/python3.11/site-packages/airflow/operators/python.py", line 256, in execute_callable
    return runner.run(*self.op_args, **self.op_kwargs)
           ^^^^^^^^^^^^^^^^^^^^^^^^^^^^^^^^^^^^^^^^^^^
  File "/home/airflow/.local/lib/python3.11/site-packages/airflow/utils/operator_helpers.py", line 252, in run
    return self.func(*args, **kwargs)
           ^^^^^^^^^^^^^^^^^^^^^^^^^^
  File "/opt/airflow/dags/dbt_snowflake_pipeline.py", line 37, in load_into_snowflake
    conn = snowflake.connector.connect(
           ^^^^^^^^^^^^^^^^^^^^^^^^^^^^
  File "/home/airflow/.local/lib/python3.11/site-packages/snowflake/connector/__init__.py", line 55, in Connect
    return SnowflakeConnection(**kwargs)
           ^^^^^^^^^^^^^^^^^^^^^^^^^^^^^
  File "/home/airflow/.local/lib/python3.11/site-packages/snowflake/connector/connection.py", line 466, in __init__
    self.connect(**kwargs)
  File "/home/airflow/.local/lib/python3.11/site-packages/snowflake/connector/connection.py", line 754, in connect
    self.__config(**kwargs)
  File "/home/airflow/.local/lib/python3.11/site-packages/snowflake/connector/connection.py", line 1215, in __config
    self._host = construct_hostname(kwargs.get("region"), self._account)
                 ^^^^^^^^^^^^^^^^^^^^^^^^^^^^^^^^^^^^^^^^^^^^^^^^^^^^^^^
  File "/home/airflow/.local/lib/python3.11/site-packages/snowflake/connector/util_text.py", line 255, in construct_hostname
    if account.find(".") > 0 and _is_china_region(account.split(".")[1]):
       ^^^^^^^^^^^^
AttributeError: 'NoneType' object has no attribute 'find'
[2025-04-17T13:37:01.355+0000] {local_task_job_runner.py:266} INFO - Task exited with return code 1
[2025-04-17T13:37:01.418+0000] {taskinstance.py:3895} INFO - 0 downstream tasks scheduled from follow-on schedule check
[2025-04-17T13:37:01.443+0000] {local_task_job_runner.py:245} INFO - ::endgroup::
